2023-06-30 15:03:10,605 - ERROR - Traceback (most recent call last):
  File "D:\.Jetbrain\PycharmProjects\DBOuput\pymysql\connections.py", line 616, in connect
    sock = socket.create_connection(
  File "D:\Program Files\.pyenv\pyenv-win\versions\3.10.10\lib\socket.py", line 845, in create_connection
    raise err
  File "D:\Program Files\.pyenv\pyenv-win\versions\3.10.10\lib\socket.py", line 833, in create_connection
    sock.connect(sa)
ConnectionRefusedError: [WinError 10061] 由于目标计算机积极拒绝，无法连接。

During handling of the above exception, another exception occurred:

Traceback (most recent call last):
  File "D:\.Jetbrain\PycharmProjects\DBOuput\MySQLOutput.py", line 76, in run_MySQL_backup
    conn = pymysql.connect(host=db_host, port=db_port, user=db_user, password=db_password, db=db_name)
  File "D:\.Jetbrain\PycharmProjects\DBOuput\pymysql\connections.py", line 352, in __init__
    self.connect()
  File "D:\.Jetbrain\PycharmProjects\DBOuput\pymysql\connections.py", line 668, in connect
    raise exc
pymysql.err.OperationalError: (2003, "Can't connect to MySQL server on 'localhost' ([WinError 10061] 由于目标计算机积极拒绝，无法连接。)")

